<?xml version="1.0"?>
<robot name="suitecase_simple" xmlns:xacro="http://ros.org/wiki/xacro">

  <!-- Base (bottom plane) -->
  <link name="base_plane">
    <inertial>
      <origin xyz="0 0 0" rpy="0 0 0"/>
      <mass value="2.0"/>
      <inertia ixx="0.01" ixy="0" ixz="0" iyy="0.02" iyz="0" izz="0.02"/>
    </inertial>
    <visual>
      <origin xyz="0 0 0" rpy="0 0 0"/>
      <geometry>
        <box size="0.50 0.30 0.05"/>
      </geometry>
      <material name="gray"><color rgba="0.5 0.5 0.5 1.0"/></material>
    </visual>
    <collision>
      <origin xyz="0 0 0" rpy="0 0 0"/>
      <geometry>
        <box size="0.50 0.30 0.05"/>
      </geometry>
    </collision>
  </link>

  <!-- Suitcase body (balances relative to base_plane) -->
  <link name="body">
    <inertial>
      <origin xyz="0 0 0" rpy="0 0 0"/>
      <mass value="5.0"/>
      <inertia ixx="0.15" ixy="0" ixz="0" iyy="0.05" iyz="0" izz="0.15"/>
    </inertial>
    <visual>
      <origin xyz="0 0 0.35" rpy="0 0 0"/>
      <geometry>
        <box size="0.40 0.25 0.60"/>
      </geometry>
      <material name="blue"><color rgba="0.1 0.3 0.8 1.0"/></material>
    </visual>
    <collision>
      <origin xyz="0 0 0.35" rpy="0 0 0"/>
      <geometry>
        <box size="0.40 0.25 0.60"/>
      </geometry>
    </collision>
  </link>

  <!-- Balance hinge joint (policy action target). Pitch about Y-axis. -->
  <joint name="balance_joint" type="revolute">
    <parent link="base_plane"/>
    <child link="body"/>
    <origin xyz="0 0 0.05" rpy="0 0 0"/>
    <axis xyz="0 1 0"/>
    <limit lower="-1.57" upper="1.57" effort="100" velocity="5"/>
    <dynamics damping="0.2" friction="0.0"/>
  </joint>

  <!-- Handle (for applying external wrenches) -->
  <link name="handle">
    <inertial>
      <origin xyz="0 0 0" rpy="0 0 0"/>
      <mass value="0.2"/>
      <inertia ixx="0.001" ixy="0" ixz="0" iyy="0.001" iyz="0" izz="0.001"/>
    </inertial>
    <visual>
      <origin xyz="0 0 0.70" rpy="0 0 0"/>
      <geometry>
        <cylinder radius="0.01" length="0.30"/>
      </geometry>
      <material name="black"><color rgba="0.1 0.1 0.1 1.0"/></material>
    </visual>
    <collision>
      <origin xyz="0 0 0.70" rpy="0 0 0"/>
      <geometry>
        <cylinder radius="0.01" length="0.30"/>
      </geometry>
    </collision>
  </link>

  <joint name="handle_fixed" type="fixed">
    <parent link="body"/>
    <child link="handle"/>
    <origin xyz="0 0 0" rpy="0 0 0"/>
  </joint>

  <!-- Wheels (free-rolling). Axes along Y so they roll in X. -->
  <link name="wheel_fl">
    <inertial>
      <origin xyz="0 0 0" rpy="0 0 0"/>
      <mass value="0.3"/>
      <inertia ixx="0.0005" ixy="0" ixz="0" iyy="0.0005" iyz="0" izz="0.0005"/>
    </inertial>
    <visual>
      <origin xyz="0 0 0" rpy="1.5708 0 0"/>
      <geometry>
        <cylinder radius="0.05" length="0.03"/>
      </geometry>
      <material name="dark"><color rgba="0.2 0.2 0.2 1.0"/></material>
    </visual>
    <collision>
      <origin xyz="0 0 0" rpy="1.5708 0 0"/>
      <geometry>
        <cylinder radius="0.05" length="0.03"/>
      </geometry>
    </collision>
  </link>

  <link name="wheel_fr">
    <inertial>
      <origin xyz="0 0 0" rpy="0 0 0"/>
      <mass value="0.3"/>
      <inertia ixx="0.0005" ixy="0" ixz="0" iyy="0.0005" iyz="0" izz="0.0005"/>
    </inertial>
    <visual>
      <origin xyz="0 0 0" rpy="1.5708 0 0"/>
      <geometry>
        <cylinder radius="0.05" length="0.03"/>
      </geometry>
      <material name="dark"/>
    </visual>
    <collision>
      <origin xyz="0 0 0" rpy="1.5708 0 0"/>
      <geometry>
        <cylinder radius="0.05" length="0.03"/>
      </geometry>
    </collision>
  </link>

  <link name="wheel_rl">
    <inertial>
      <origin xyz="0 0 0" rpy="0 0 0"/>
      <mass value="0.3"/>
      <inertia ixx="0.0005" ixy="0" ixz="0" iyy="0.0005" iyz="0" izz="0.0005"/>
    </inertial>
    <visual>
      <origin xyz="0 0 0" rpy="1.5708 0 0"/>
      <geometry>
        <cylinder radius="0.05" length="0.03"/>
      </geometry>
      <material name="dark"/>
    </visual>
    <collision>
      <origin xyz="0 0 0" rpy="1.5708 0 0"/>
      <geometry>
        <cylinder radius="0.05" length="0.03"/>
      </geometry>
    </collision>
  </link>

  <link name="wheel_rr">
    <inertial>
      <origin xyz="0 0 0" rpy="0 0 0"/>
      <mass value="0.3"/>
      <inertia ixx="0.0005" ixy="0" ixz="0" iyy="0.0005" iyz="0" izz="0.0005"/>
    </inertial>
    <visual>
      <origin xyz="0 0 0" rpy="1.5708 0 0"/>
      <geometry>
        <cylinder radius="0.05" length="0.03"/>
      </geometry>
      <material name="dark"/>
    </visual>
    <collision>
      <origin xyz="0 0 0" rpy="1.5708 0 0"/>
      <geometry>
        <cylinder radius="0.05" length="0.03"/>
      </geometry>
    </collision>
  </link>

  <!-- Wheel joints: continuous rotation around Y-axis -->
  <joint name="wheel_fl_joint" type="continuous">
    <parent link="base_plane"/>
    <child link="wheel_fl"/>
    <origin xyz="0.20 0.12 -0.075" rpy="0 0 0"/>
    <axis xyz="0 1 0"/>
    <dynamics damping="0.0" friction="0.0"/>
  </joint>

  <joint name="wheel_fr_joint" type="continuous">
    <parent link="base_plane"/>
    <child link="wheel_fr"/>
    <origin xyz="0.20 -0.12 -0.075" rpy="0 0 0"/>
    <axis xyz="0 1 0"/>
    <dynamics damping="0.0" friction="0.0"/>
  </joint>

  <joint name="wheel_rl_joint" type="continuous">
    <parent link="base_plane"/>
    <child link="wheel_rl"/>
    <origin xyz="-0.20 0.12 -0.075" rpy="0 0 0"/>
    <axis xyz="0 1 0"/>
    <dynamics damping="0.0" friction="0.0"/>
  </joint>

  <joint name="wheel_rr_joint" type="continuous">
    <parent link="base_plane"/>
    <child link="wheel_rr"/>
    <origin xyz="-0.20 -0.12 -0.075" rpy="0 0 0"/>
    <axis xyz="0 1 0"/>
    <dynamics damping="0.0" friction="0.0"/>
  </joint>

</robot>

