<?xml version="1.0" ?>
<robot name="Auto_Balancing_Case" xmlns:xacro="http://www.ros.org/wiki/xacro">

  <!-- simple inline material since xacro includes are removed -->
  <material name="silver">
    <color rgba="0.75 0.75 0.75 1.0"/>
  </material>

  
<link name="base_link">
  <inertial>
    <origin xyz="0.17999999999999997 0.115 0.005003006827026274" rpy="0 0 0"/>
    <mass value="0.9847218407587564"/>
    <inertia ixx="0.004346" iyy="0.010634" izz="0.014964" ixy="-0.0" iyz="0.0" ixz="-0.0"/>
  </inertial>
  <visual>
    <origin xyz="0.18 0.115 0.005" rpy="0 0 0"/>
    <geometry>
      <box size="0.36 0.23 0.01"/>
    </geometry>
    <material name="silver"/>
  </visual>
  <collision>
    <origin xyz="0.18 0.115 0.005" rpy="0 0 0"/>
    <geometry>
      <box size="0.36 0.23 0.01"/>
    </geometry>
  </collision>
</link>

<link name="handle">
  <inertial>
    <origin xyz="0.0 0.0 0.0" rpy="0 0 0"/>
    <mass value="0.0"/>
    <inertia ixx="0.0" iyy="0.0" izz="0.0" ixy="-0.0" iyz="0.0" ixz="-0.0"/>
  </inertial>
  <visual>
    <origin xyz="0.0 0.005 0.35" rpy="0 0 0"/>
    <geometry>
      <box size="0.15 0.01 0.35"/>
    </geometry>
    <material name="silver"/>
  </visual>
  <collision>
    <origin xyz="0.0 0.005 0.35" rpy="0 0 0"/>
    <geometry>
      <box size="0.15 0.01 0.35"/>
    </geometry>
  </collision>
</link>

<link name="FR_wheelbase_1">
  <inertial>
    <origin xyz="0.004854891037663869 0.0 -0.01224396424044122" rpy="0 0 0"/>
    <mass value="0.026348088954006088"/>
    <inertia ixx="5e-06" iyy="4e-06" izz="5e-06" ixy="-0.0" iyz="0.0" ixz="1e-06"/>
  </inertial>
</link>

<link name="RR_wheelbase_1">
  <inertial>
    <origin xyz="0.004821350892733667 -2.7755575615628914e-17 -0.012195503618703826" rpy="0 0 0"/>
    <mass value="0.02614973311170209"/>
    <inertia ixx="5e-06" iyy="4e-06" izz="5e-06" ixy="-0.0" iyz="0.0" ixz="1e-06"/>
  </inertial>
</link>

<link name="FL_wheelbase_1">
  <inertial>
    <origin xyz="0.0048548910376638756 -1.0408340855860843e-17 -0.012243964240441205" rpy="0 0 0"/>
    <mass value="0.02634808895400608"/>
    <inertia ixx="5e-06" iyy="4e-06" izz="5e-06" ixy="-0.0" iyz="-0.0" ixz="1e-06"/>
  </inertial>
</link>

<link name="RL_wheelbase_1">
  <inertial>
    <origin xyz="0.004821350892733667 -2.7755575615628914e-17 -0.012195503618703807" rpy="0 0 0"/>
    <mass value="0.02614973311170209"/>
    <inertia ixx="5e-06" iyy="4e-06" izz="5e-06" ixy="-0.0" iyz="-0.0" ixz="1e-06"/>
  </inertial>
</link>

<link name="FL_wheel_1">
  <inertial>
    <origin xyz="5.988265439071938e-15 -3.469446951953614e-18 1.3877787807814457e-17" rpy="0 0 0"/>
    <mass value="0.04246628391615553"/>
    <inertia ixx="2.4e-05" iyy="1.3e-05" izz="2.4e-05" ixy="-0.0" iyz="0.0" ixz="0.0"/>
  </inertial>
  <visual>
    <origin xyz="0 0 0" rpy="-1.5708 0 0"/>
    <geometry>
      <cylinder radius="0.025" length="0.05"/>
    </geometry>
    <material name="silver"/>
  </visual>
  <collision>
    <origin xyz="0 0 0" rpy="-1.5708 0 0"/>
    <geometry>
      <cylinder radius="0.025" length="0.05"/>
    </geometry>
  </collision>
</link>

<link name="RR_wheel_1">
  <inertial>
    <origin xyz="-1.3006670518400654e-07 0.0 -2.0816681711721685e-17" rpy="0 0 0"/>
    <mass value="0.042466283916155555"/>
    <inertia ixx="2.4e-05" iyy="1.3e-05" izz="2.4e-05" ixy="0.0" iyz="-0.0" ixz="0.0"/>
  </inertial>
  <visual>
    <origin xyz="0 0 0" rpy="-1.5708 0 0"/>
    <geometry>
      <cylinder radius="0.025" length="0.05"/>
    </geometry>
    <material name="silver"/>
  </visual>
  <collision>
    <origin xyz="0 0 0" rpy="-1.5708 0 0"/>
    <geometry>
      <cylinder radius="0.025" length="0.05"/>
    </geometry>
  </collision>
</link>

<link name="FR_wheel_1">
  <inertial>
    <origin xyz="6.0021432268797525e-15 0.0 1.3877787807814457e-17" rpy="0 0 0"/>
    <mass value="0.04246628391615553"/>
    <inertia ixx="2.4e-05" iyy="1.3e-05" izz="2.4e-05" ixy="0.0" iyz="0.0" ixz="0.0"/>
  </inertial>
  <visual>
    <origin xyz="0 0 0" rpy="-1.5708 0 0"/>
    <geometry>
      <cylinder radius="0.025" length="0.05"/>
    </geometry>
    <material name="silver"/>
  </visual>
  <collision>
    <origin xyz="0 0 0" rpy="-1.5708 0 0"/>
    <geometry>
      <cylinder radius="0.025" length="0.05"/>
    </geometry>
  </collision>
</link>

<link name="RL_wheel_1">
  <inertial>
    <origin xyz="-1.3006670512849539e-07 6.245004513516506e-17 0.0" rpy="0 0 0"/>
    <mass value="0.042466283916155555"/>
    <inertia ixx="2.4e-05" iyy="1.3e-05" izz="2.4e-05" ixy="-0.0" iyz="0.0" ixz="0.0"/>
  </inertial>
  <visual>
    <origin xyz="0 0 0" rpy="-1.5708 0 0"/>
    <geometry>
      <cylinder radius="0.025" length="0.05"/>
    </geometry>
    <material name="silver"/>
  </visual>
  <collision>
    <origin xyz="0 0 0" rpy="-1.5708 0 0"/>
    <geometry>
      <cylinder radius="0.025" length="0.05"/>
    </geometry>
  </collision>
</link>

<link name="luggage_case_1">
  <inertial>
    <origin xyz="1.0107192860431269e-12 0.1113836158375588 0.19099105534572558" rpy="0 0 0"/>
    <mass value="5.601340756429785"/>
    <inertia ixx="0.281154" iyy="0.307224" izz="0.120645" ixy="-0.0" iyz="0.010699" ixz="0.0"/>
  </inertial>
  <visual>
    <origin xyz="0.0 0.115 0.29688" rpy="0 0 0"/>
    <geometry>
      <box size="0.36 0.23 0.5"/>
    </geometry>
    <material name="silver"/>
  </visual>
  <collision>
    <origin xyz="0.0 0.115 0.29688" rpy="0 0 0"/>
    <geometry>
      <box size="0.36 0.23 0.5"/>
    </geometry>
  </collision>
</link>

<joint name="Revolute 1" type="continuous">
  <origin xyz="0.02 0.21 0.0001" rpy="0 0 0"/>
  <parent link="base_link"/>
  <child link="FR_wheelbase_1"/>
  <axis xyz="0.0 0.0 -1.0"/>
</joint>

<joint name="Revolute 2" type="continuous">
  <origin xyz="0.34 0.21 0.0001" rpy="0 0 0"/>
  <parent link="base_link"/>
  <child link="RR_wheelbase_1"/>
  <axis xyz="0.0 0.0 -1.0"/>
</joint>

<joint name="Revolute 3" type="continuous">
  <origin xyz="0.02 0.02 0.0001" rpy="0 0 0"/>
  <parent link="base_link"/>
  <child link="FL_wheelbase_1"/>
  <axis xyz="0.0 0.0 -1.0"/>
</joint>

<joint name="Revolute 4" type="continuous">
  <origin xyz="0.34 0.02 0.0001" rpy="0 0 0"/>
  <parent link="base_link"/>
  <child link="RL_wheelbase_1"/>
  <axis xyz="0.0 0.0 -1.0"/>
</joint>

<joint name="Revolute 5" type="continuous">
  <origin xyz="0.02 0.0 -0.035" rpy="0 0 0"/>
  <parent link="FL_wheelbase_1"/>
  <child link="FL_wheel_1"/>
  <axis xyz="0.0 1.0 0.0"/>
</joint>

<joint name="Revolute 6" type="continuous">
  <origin xyz="0.01992 0.0 -0.035" rpy="0 0 0"/>
  <parent link="RR_wheelbase_1"/>
  <child link="RR_wheel_1"/>
  <axis xyz="0.0 1.0 0.0"/>
</joint>

<joint name="Revolute 7" type="continuous">
  <origin xyz="0.02 0.0 -0.035" rpy="0 0 0"/>
  <parent link="FR_wheelbase_1"/>
  <child link="FR_wheel_1"/>
  <axis xyz="0.0 1.0 0.0"/>
</joint>

<joint name="Revolute 8" type="continuous">
  <origin xyz="0.01992 0.0 -0.035" rpy="0 0 0"/>
  <parent link="RL_wheelbase_1"/>
  <child link="RL_wheel_1"/>
  <axis xyz="0.0 1.0 0.0"/>
</joint>

  <joint name="Revolute_motor" type="revolute">
    <origin xyz="0.18 0.0 0.06" rpy="0 0 0"/>
    <parent link="base_link"/>
    <child link="luggage_case_1"/>
    <axis xyz="0.0 -1.0 0.0"/>
    <limit lower="-0.5236" upper="0.5236" effort="3.0" velocity="6.2832"/>
  </joint>

<joint name="Fixed_handle" type="fixed">
  <origin xyz="0.0 -0.0 0.366188" rpy="0 0 0"/>
  <parent link="luggage_case_1"/>
  <child link="handle"/>
  <axis xyz="0.0 0.0 0.0"/>
</joint>

</robot>

